Workbook
Name Slicer_Charts: #N/A
Name week_5: Game!$A$59:$Z$71
Name week_6: Game!$A$73:$Z$85
Name week_7: Game!$A$87:$Z$99
Name Week1: Game!$A$2:$Z$15
Name week2: Game!$A$17:$Z$29
Name week3: Game!$A$31:$Z$43
Name week4: Game!$A$46:$Z$57

Sheet Game
A1: Pj | B1: Hobbies / Activities | P1: Quaities
B2: Wakeup @ 6am (3pts) | C2: Bootup (3pts) | D2: Research & Study (4pts/3pts pr hr) | E2: Gym (6pts) | F2: Work (1pt/hr) | G2: Overtime (1pt/hr) | H2: Cooking (2pts) | I2: Art (Depends) | J2: Chess (2/1/.5pts) | K2: Binge (1pt/hr) | L2: Resist (2pts) | M2: Help others (1pt/hr) | N2: Journal (2pts) | O2: Sleep by 11pm (3pts) | P2: Diet & Hydration (4pts) | Q2: Pace & Intensity (3pts) | R2: Cleanliness(2pts) & Heigine (1pt) | S2: Integrity (3pts) | T2: Bonus (depends) | U2: Penalties (depends) | V2: Vibe Check (5pts) | W2: Total | X2: Streak Bonus | Y2: Total (with Bonus) | Z2: Comments (title of the day)/(rant)(vent)/(How was ur day) | AA2: Gratitude | AB2: Cumulative Days | AD2: {=_xlfn.LET( _xlpm.clean,TRIM(LEFT(B2,FIND("(",B2&"(")-1)), _xlpm.tokens,_xlfn.TEXTSPLIT(_xlpm.clean," "), _xlpm.n,COUNTA(_xlpm.tokens), IF( _xlpm.n<=2, _xlpm.clean, _xlfn.TEXTJOIN( " ", , _xlfn.MAP( _xlpm.tokens, _xlfn.LAMBDA(_xlpm.t, IF( OR( _xlpm.t="&", SUM(--ISNUMBER(SEARCH({0,1,2,3,4,5,6,7,8,9},_xlpm.t)))>0 ), _xlpm.t, LEFT(_xlpm.t,1) ) ) ) ) ))} -> W @ 6am | AE2: {=_xlfn.LET( _xlpm.clean,TRIM(LEFT(C2,FIND("(",C2&"(")-1)), _xlpm.tokens,_xlfn.TEXTSPLIT(_xlpm.clean," "), _xlpm.n,COUNTA(_xlpm.tokens), IF( _xlpm.n<=2, _xlpm.clean, _xlfn.TEXTJOIN( " ", , _xlfn.MAP( _xlpm.tokens, _xlfn.LAMBDA(_xlpm.t, IF( OR( _xlpm.t="&", SUM(--ISNUMBER(SEARCH({0,1,2,3,4,5,6,7,8,9},_xlpm.t)))>0 ), _xlpm.t, LEFT(_xlpm.t,1) ) ) ) ) ))} -> Bootup | AF2: {=_xlfn.LET( _xlpm.clean,TRIM(LEFT(D2,FIND("(",D2&"(")-1)), _xlpm.tokens,_xlfn.TEXTSPLIT(_xlpm.clean," "), _xlpm.n,COUNTA(_xlpm.tokens), IF( _xlpm.n<=2, _xlpm.clean, _xlfn.TEXTJOIN( " ", , _xlfn.MAP( _xlpm.tokens, _xlfn.LAMBDA(_xlpm.t, IF( OR( _xlpm.t="&", SUM(--ISNUMBER(SEARCH({0,1,2,3,4,5,6,7,8,9},_xlpm.t)))>0 ), _xlpm.t, LEFT(_xlpm.t,1) ) ) ) ) ))} -> R & S | AG2: {=_xlfn.LET( _xlpm.clean,TRIM(LEFT(E2,FIND("(",E2&"(")-1)), _xlpm.tokens,_xlfn.TEXTSPLIT(_xlpm.clean," "), _xlpm.n,COUNTA(_xlpm.tokens), IF( _xlpm.n<=2, _xlpm.clean, _xlfn.TEXTJOIN( " ", , _xlfn.MAP( _xlpm.tokens, _xlfn.LAMBDA(_xlpm.t, IF( OR( _xlpm.t="&", SUM(--ISNUMBER(SEARCH({0,1,2,3,4,5,6,7,8,9},_xlpm.t)))>0 ), _xlpm.t, LEFT(_xlpm.t,1) ) ) ) ) ))} -> Gym | AH2: {=_xlfn.LET( _xlpm.clean,TRIM(LEFT(F2,FIND("(",F2&"(")-1)), _xlpm.tokens,_xlfn.TEXTSPLIT(_xlpm.clean," "), _xlpm.n,COUNTA(_xlpm.tokens), IF( _xlpm.n<=2, _xlpm.clean, _xlfn.TEXTJOIN( " ", , _xlfn.MAP( _xlpm.tokens, _xlfn.LAMBDA(_xlpm.t, IF( OR( _xlpm.t="&", SUM(--ISNUMBER(SEARCH({0,1,2,3,4,5,6,7,8,9},_xlpm.t)))>0 ), _xlpm.t, LEFT(_xlpm.t,1) ) ) ) ) ))} -> Work | AI2: {=_xlfn.LET( _xlpm.clean,TRIM(LEFT(G2,FIND("(",G2&"(")-1)), _xlpm.tokens,_xlfn.TEXTSPLIT(_xlpm.clean," "), _xlpm.n,COUNTA(_xlpm.tokens), IF( _xlpm.n<=2, _xlpm.clean, _xlfn.TEXTJOIN( " ", , _xlfn.MAP( _xlpm.tokens, _xlfn.LAMBDA(_xlpm.t, IF( OR( _xlpm.t="&", SUM(--ISNUMBER(SEARCH({0,1,2,3,4,5,6,7,8,9},_xlpm.t)))>0 ), _xlpm.t, LEFT(_xlpm.t,1) ) ) ) ) ))} -> Overtime | AJ2: {=_xlfn.LET( _xlpm.clean,TRIM(LEFT(H2,FIND("(",H2&"(")-1)), _xlpm.tokens,_xlfn.TEXTSPLIT(_xlpm.clean," "), _xlpm.n,COUNTA(_xlpm.tokens), IF( _xlpm.n<=2, _xlpm.clean, _xlfn.TEXTJOIN( " ", , _xlfn.MAP( _xlpm.tokens, _xlfn.LAMBDA(_xlpm.t, IF( OR( _xlpm.t="&", SUM(--ISNUMBER(SEARCH({0,1,2,3,4,5,6,7,8,9},_xlpm.t)))>0 ), _xlpm.t, LEFT(_xlpm.t,1) ) ) ) ) ))} -> Cooking | AK2: {=_xlfn.LET( _xlpm.clean,TRIM(LEFT(I2,FIND("(",I2&"(")-1)), _xlpm.tokens,_xlfn.TEXTSPLIT(_xlpm.clean," "), _xlpm.n,COUNTA(_xlpm.tokens), IF( _xlpm.n<=2, _xlpm.clean, _xlfn.TEXTJOIN( " ", , _xlfn.MAP( _xlpm.tokens, _xlfn.LAMBDA(_xlpm.t, IF( OR( _xlpm.t="&", SUM(--ISNUMBER(SEARCH({0,1,2,3,4,5,6,7,8,9},_xlpm.t)))>0 ), _xlpm.t, LEFT(_xlpm.t,1) ) ) ) ) ))} -> Art | ... AW2: {=_xlfn.LET( _xlpm.clean,TRIM(LEFT(U2,FIND("(",U2&"(")-1)), _xlpm.tokens,_xlfn.TEXTSPLIT(_xlpm.clean," "), _xlpm.n,COUNTA(_xlpm.tokens), IF( _xlpm.n<=2, _xlpm.clean, _xlfn.TEXTJOIN( " ", , _xlfn.MAP( _xlpm.tokens, _xlfn.LAMBDA(_xlpm.t, IF( OR( _xlpm.t="&", SUM(--ISNUMBER(SEARCH({0,1,2,3,4,5,6,7,8,9},_xlpm.t)))>0 ), _xlpm.t, LEFT(_xlpm.t,1) ) ) ) ) ))} -> Penalties | AY2: =AD2 -> W @ 6am | AZ2: =AE2 -> Bootup | BA2: =AF2 -> R & S | BB2: =AG2 -> Gym | BC2: =AH2 -> Work | BD2: =AI2 -> Overtime | BE2: =AJ2 -> Cooking | BF2: =AK2 -> Art | ... BR2: =AW2 -> Penalties | BS2: Total | BT2: Streak Bonus | BU2: Total with bonus
A3: Week 1 | B3: Enter your start date : | D3: 46027 | E3: =D3+6 -> 46033 | F3: Goal(s) by week 12: | H3: Set Only 1 or few goals. | AC3: W1 | BS3: 0 | BU3: 0
A4: Mon (e.g->) | B4: 2 | D4: 5 | E4: 9 | F4: 4 | I4: 3 | K4: 0.75 | L4: 2 | M4: 1 | N4: 2.5 | O4: 2 | R4: 1 | S4: 3 | U4: -1 | V4: 2 | W4: =SUM(B4:V4) -> 36.25 | X4: =SUM(AD4:AW4)*0.1 -> 0.12 | Y4: =W4+X4 -> 36.37 | Z4: e.g1: art of doing nothin (erase and write ur title of the day) | AB4: =W4 -> 36.25 | AC4: Mon | AD4: =IF(B4 > 0, IF(AD3 > 0, AD3 + 1, 0.1), 0) -> 0.1 | AE4: =IF(C4 > 0, IF(AE3 > 0, AE3 + 1, 0.1), 0) -> 0 | AF4: =IF(D4 > 0, IF(AF3 > 0, AF3 + 1, 0.1), 0) -> 0.1 | AG4: =IF(E4 > 0, IF(AG3 > 0, AG3 + 1, 0.1), 0) -> 0.1 | AH4: =IF(F4 > 0, IF(AH3 > 0, AH3 + 1, 0.1), 0) -> 0.1 | AI4: =IF(G4 > 0, IF(AI3 > 0, AI3 + 1, 0.1), 0) -> 0 | AJ4: =IF(H4 > 0, IF(AJ3 > 0, AJ3 + 1, 0.1), 0) -> 0 | AK4: =IF(I4 > 0, IF(AK3 > 0, AK3 + 1, 0.1), 0) -> 0.1 | ... AW4: =IF(U4 > 0, IF(AW3 > 0, AW3 + 1, 0.1), 0) -> 0 | AY4: =SUM($B$4:B4) -> 2 | AZ4: =SUM($B$4:C4) -> 2 | BA4: =SUM($B$4:D4) -> 7 | BB4: =SUM($B$4:E4) -> 16 | BC4: =SUM($B$4:F4) -> 20 | BD4: =SUM($B$4:G4) -> 20 | BE4: =SUM($B$4:H4) -> 20 | BF4: =SUM($B$4:I4) -> 23 | ... BJ4: =SUM($B$4:M4) -> 26.75 | BK4: =SUM($B$4:Q4) -> 31.25 | BL4: =SUM($B$4:N4) -> 29.25 | BM4: =SUM($B$4:O4) -> 31.25 | BN4: =SUM($B$4:P4) -> 31.25 | BO4: =SUM($B$4:R4) -> 32.25 | BP4: =SUM($B$4:S4) -> 35.25 | BQ4: =SUM($B$4:T4) -> 35.25 | BR4: =SUM($B$4:V4) -> 36.25 | BS4: =SUM($W$4:W4) -> 36.25 | BT4: =BR4+X4 -> 36.37 | BU4: =SUM($BT$4:BT4) -> 36.37
A5: Tue | W5: =SUM(B5:V5) -> 0 | X5: =SUM(AD5:AW5)*0.1 -> 0 | Y5: =W5+X5 -> 0 | AB5: =W5 -> 0 | AC5: Tue | AD5: =IF(B5 > 0, IF(AD4 > 0, AD4 + 1, 0.1), 0) -> 0 | AE5: =IF(C5 > 0, IF(AE4 > 0, AE4 + 1, 0.1), 0) -> 0 | AF5: =IF(D5 > 0, IF(AF4 > 0, AF4 + 1, 0.1), 0) -> 0 | AG5: =IF(E5 > 0, IF(AG4 > 0, AG4 + 1, 0.1), 0) -> 0 | AH5: =IF(F5 > 0, IF(AH4 > 0, AH4 + 1, 0.1), 0) -> 0 | AI5: =IF(G5 > 0, IF(AI4 > 0, AI4 + 1, 0.1), 0) -> 0 | AJ5: =IF(H5 > 0, IF(AJ4 > 0, AJ4 + 1, 0.1), 0) -> 0 | AK5: =IF(I5 > 0, IF(AK4 > 0, AK4 + 1, 0.1), 0) -> 0 | ... AW5: =IF(U5 > 0, IF(AW4 > 0, AW4 + 1, 0.1), 0) -> 0 | AY5: =SUM($B$5:B5) -> 0 | AZ5: =SUM($B$5:C5) -> 0 | BA5: =SUM($B$5:D5) -> 0 | BB5: =SUM($B$5:E5) -> 0 | BC5: =SUM($B$5:F5) -> 0 | BD5: =SUM($B$5:G5) -> 0 | BE5: =SUM($B$5:H5) -> 0 | BF5: =SUM($B$5:I5) -> 0 | ... BJ5: =SUM($B$5:M5) -> 0 | BK5: =SUM($B$5:Q5) -> 0 | BL5: =SUM($B$5:N5) -> 0 | BM5: =SUM($B$5:O5) -> 0 | BN5: =SUM($B$5:P5) -> 0 | BO5: =SUM($B$5:R5) -> 0 | BP5: =SUM($B$5:S5) -> 0 | BQ5: =SUM($B$5:T5) -> 0 | BR5: =SUM($B$5:V5) -> 0 | BS5: =SUM($W$4:W5) -> 36.25 | BT5: =BR5+X5 -> 0 | BU5: =SUM($BT$4:BT5) -> 36.37
A6: Wed | W6: =SUM(B6:U6) -> 0 | X6: =SUM(AD6:AW6)*0.1 -> 0 | Y6: =W6+X6 -> 0 | AB6: =W6 -> 0 | AC6: Wed | AD6: =IF(B6 > 0, IF(AD5 > 0, AD5 + 1, 0.1), 0) -> 0 | AE6: =IF(C6 > 0, IF(AE5 > 0, AE5 + 1, 0.1), 0) -> 0 | AF6: =IF(D6 > 0, IF(AF5 > 0, AF5 + 1, 0.1), 0) -> 0 | AG6: =IF(E6 > 0, IF(AG5 > 0, AG5 + 1, 0.1), 0) -> 0 | AH6: =IF(F6 > 0, IF(AH5 > 0, AH5 + 1, 0.1), 0) -> 0 | AI6: =IF(G6 > 0, IF(AI5 > 0, AI5 + 1, 0.1), 0) -> 0 | AJ6: =IF(H6 > 0, IF(AJ5 > 0, AJ5 + 1, 0.1), 0) -> 0 | AK6: =IF(I6 > 0, IF(AK5 > 0, AK5 + 1, 0.1), 0) -> 0 | ... AW6: =IF(U6 > 0, IF(AW5 > 0, AW5 + 1, 0.1), 0) -> 0 | AY6: =SUM($B$6:B6) -> 0 | AZ6: =SUM($B$6:C6) -> 0 | BA6: =SUM($B$6:D6) -> 0 | BB6: =SUM($B$6:E6) -> 0 | BC6: =SUM($B$6:F6) -> 0 | BD6: =SUM($B$6:G6) -> 0 | BE6: =SUM($B$6:H6) -> 0 | BF6: =SUM($B$6:I6) -> 0 | ... BJ6: =SUM($B$6:M6) -> 0 | BK6: =SUM($B$6:Q6) -> 0 | BL6: =SUM($B$6:N6) -> 0 | BM6: =SUM($B$6:O6) -> 0 | BN6: =SUM($B$6:P6) -> 0 | BO6: =SUM($B$6:R6) -> 0 | BP6: =SUM($B$6:S6) -> 0 | BQ6: =SUM($B$6:T6) -> 0 | BR6: =SUM($B$6:V6) -> 0 | BS6: =SUM($W$4:W6) -> 36.25 | BT6: =BR6+X6 -> 0 | BU6: =SUM($BT$4:BT6) -> 36.37
A7: Thu | W7: =SUM(B7:U7) -> 0 | X7: =SUM(AD7:AW7)*0.1 -> 0 | Y7: =W7+X7 -> 0 | AB7: =W7 -> 0 | AC7: Thu | AD7: =IF(B7 > 0, IF(AD6 > 0, AD6 + 1, 0.1), 0) -> 0 | AE7: =IF(C7 > 0, IF(AE6 > 0, AE6 + 1, 0.1), 0) -> 0 | AF7: =IF(D7 > 0, IF(AF6 > 0, AF6 + 1, 0.1), 0) -> 0 | AG7: =IF(E7 > 0, IF(AG6 > 0, AG6 + 1, 0.1), 0) -> 0 | AH7: =IF(F7 > 0, IF(AH6 > 0, AH6 + 1, 0.1), 0) -> 0 | AI7: =IF(G7 > 0, IF(AI6 > 0, AI6 + 1, 0.1), 0) -> 0 | AJ7: =IF(H7 > 0, IF(AJ6 > 0, AJ6 + 1, 0.1), 0) -> 0 | AK7: =IF(I7 > 0, IF(AK6 > 0, AK6 + 1, 0.1), 0) -> 0 | ... AW7: =IF(U7 > 0, IF(AW6 > 0, AW6 + 1, 0.1), 0) -> 0 | AY7: =SUM($B$7:B7) -> 0 | AZ7: =SUM($B$7:C7) -> 0 | BA7: =SUM($B$7:D7) -> 0 | BB7: =SUM($B$7:E7) -> 0 | BC7: =SUM($B$7:F7) -> 0 | BD7: =SUM($B$7:G7) -> 0 | BE7: =SUM($B$7:H7) -> 0 | BF7: =SUM($B$7:I7) -> 0 | ... BJ7: =SUM($B$7:M7) -> 0 | BK7: =SUM($B$7:Q7) -> 0 | BL7: =SUM($B$7:N7) -> 0 | BM7: =SUM($B$7:O7) -> 0 | BN7: =SUM($B$7:P7) -> 0 | BO7: =SUM($B$7:R7) -> 0 | BP7: =SUM($B$7:S7) -> 0 | BQ7: =SUM($B$7:T7) -> 0 | BR7: =SUM($B$7:V7) -> 0 | BS7: =SUM($W$4:W7) -> 36.25 | BT7: =BR7+X7 -> 0 | BU7: =SUM($BT$4:BT7) -> 36.37
A8: Fri | W8: =SUM(B8:U8) -> 0 | X8: =SUM(AD8:AW8)*0.1 -> 0 | Y8: =W8+X8 -> 0 | AB8: =W8 -> 0 | AC8: Fri | AD8: =IF(B8 > 0, IF(AD7 > 0, AD7 + 1, 0.1), 0) -> 0 | AE8: =IF(C8 > 0, IF(AE7 > 0, AE7 + 1, 0.1), 0) -> 0 | AF8: =IF(D8 > 0, IF(AF7 > 0, AF7 + 1, 0.1), 0) -> 0 | AG8: =IF(E8 > 0, IF(AG7 > 0, AG7 + 1, 0.1), 0) -> 0 | AH8: =IF(F8 > 0, IF(AH7 > 0, AH7 + 1, 0.1), 0) -> 0 | AI8: =IF(G8 > 0, IF(AI7 > 0, AI7 + 1, 0.1), 0) -> 0 | AJ8: =IF(H8 > 0, IF(AJ7 > 0, AJ7 + 1, 0.1), 0) -> 0 | AK8: =IF(I8 > 0, IF(AK7 > 0, AK7 + 1, 0.1), 0) -> 0 | ... AW8: =IF(U8 > 0, IF(AW7 > 0, AW7 + 1, 0.1), 0) -> 0 | AY8: =SUM($B$8:B8) -> 0 | AZ8: =SUM($B$8:C8) -> 0 | BA8: =SUM($B$8:D8) -> 0 | BB8: =SUM($B$8:E8) -> 0 | BC8: =SUM($B$8:F8) -> 0 | BD8: =SUM($B$8:G8) -> 0 | BE8: =SUM($B$8:H8) -> 0 | BF8: =SUM($B$8:I8) -> 0 | ... BJ8: =SUM($B$8:M8) -> 0 | BK8: =SUM($B$8:Q8) -> 0 | BL8: =SUM($B$8:N8) -> 0 | BM8: =SUM($B$8:O8) -> 0 | BN8: =SUM($B$8:P8) -> 0 | BO8: =SUM($B$8:R8) -> 0 | BP8: =SUM($B$8:S8) -> 0 | BQ8: =SUM($B$8:T8) -> 0 | BR8: =SUM($B$8:V8) -> 0 | BS8: =SUM($W$4:W8) -> 36.25 | BT8: =BR8+X8 -> 0 | BU8: =SUM($BT$4:BT8) -> 36.37
A9: Sat | W9: =SUM(B9:U9) -> 0 | X9: =SUM(AD9:AW9)*0.1 -> 0 | Y9: =W9+X9 -> 0 | AB9: =W9 -> 0 | AC9: Sat | AD9: =IF(B9 > 0, IF(AD8 > 0, AD8 + 1, 0.1), 0) -> 0 | AE9: =IF(C9 > 0, IF(AE8 > 0, AE8 + 1, 0.1), 0) -> 0 | AF9: =IF(D9 > 0, IF(AF8 > 0, AF8 + 1, 0.1), 0) -> 0 | AG9: =IF(E9 > 0, IF(AG8 > 0, AG8 + 1, 0.1), 0) -> 0 | AH9: =IF(F9 > 0, IF(AH8 > 0, AH8 + 1, 0.1), 0) -> 0 | AI9: =IF(G9 > 0, IF(AI8 > 0, AI8 + 1, 0.1), 0) -> 0 | AJ9: =IF(H9 > 0, IF(AJ8 > 0, AJ8 + 1, 0.1), 0) -> 0 | AK9: =IF(I9 > 0, IF(AK8 > 0, AK8 + 1, 0.1), 0) -> 0 | ... AW9: =IF(U9 > 0, IF(AW8 > 0, AW8 + 1, 0.1), 0) -> 0 | AY9: =SUM($B$9:B9) -> 0 | AZ9: =SUM($B$9:C9) -> 0 | BA9: =SUM($B$9:D9) -> 0 | BB9: =SUM($B$9:E9) -> 0 | BC9: =SUM($B$9:F9) -> 0 | BD9: =SUM($B$9:G9) -> 0 | BE9: =SUM($B$9:H9) -> 0 | BF9: =SUM($B$9:I9) -> 0 | ... BJ9: =SUM($B$9:M9) -> 0 | BK9: =SUM($B$9:Q9) -> 0 | BL9: =SUM($B$9:N9) -> 0 | BM9: =SUM($B$9:O9) -> 0 | BN9: =SUM($B$9:P9) -> 0 | BO9: =SUM($B$9:R9) -> 0 | BP9: =SUM($B$9:S9) -> 0 | BQ9: =SUM($B$9:T9) -> 0 | BR9: =SUM($B$9:V9) -> 0 | BS9: =SUM($W$4:W9) -> 36.25 | BT9: =BR9+X9 -> 0 | BU9: =SUM($BT$4:BT9) -> 36.37
A10: Sun | W10: =SUM(B10:U10) -> 0 | X10: =SUM(AD10:AW10)*0.1 -> 0 | Y10: =W10+X10 -> 0 | AA10: e.g 1 - thanks to omar for inviting me to dinner | AB10: =W10 -> 0 | AC10: Sun | AD10: =IF(B10 > 0, IF(AD9 > 0, AD9 + 1, 0.1), 0) -> 0 | AE10: =IF(C10 > 0, IF(AE9 > 0, AE9 + 1, 0.1), 0) -> 0 | AF10: =IF(D10 > 0, IF(AF9 > 0, AF9 + 1, 0.1), 0) -> 0 | AG10: =IF(E10 > 0, IF(AG9 > 0, AG9 + 1, 0.1), 0) -> 0 | AH10: =IF(F10 > 0, IF(AH9 > 0, AH9 + 1, 0.1), 0) -> 0 | AI10: =IF(G10 > 0, IF(AI9 > 0, AI9 + 1, 0.1), 0) -> 0 | AJ10: =IF(H10 > 0, IF(AJ9 > 0, AJ9 + 1, 0.1), 0) -> 0 | AK10: =IF(I10 > 0, IF(AK9 > 0, AK9 + 1, 0.1), 0) -> 0 | ... AW10: =IF(U10 > 0, IF(AW9 > 0, AW9 + 1, 0.1), 0) -> 0 | AY10: =SUM($B$10:B10) -> 0 | AZ10: =SUM($B$10:C10) -> 0 | BA10: =SUM($B$10:D10) -> 0 | BB10: =SUM($B$10:E10) -> 0 | BC10: =SUM($B$10:F10) -> 0 | BD10: =SUM($B$10:G10) -> 0 | BE10: =SUM($B$10:H10) -> 0 | BF10: =SUM($B$10:I10) -> 0 | ... BJ10: =SUM($B$10:M10) -> 0 | BK10: =SUM($B$10:Q10) -> 0 | BL10: =SUM($B$10:N10) -> 0 | BM10: =SUM($B$10:O10) -> 0 | BN10: =SUM($B$10:P10) -> 0 | BO10: =SUM($B$10:R10) -> 0 | BP10: =SUM($B$10:S10) -> 0 | BQ10: =SUM($B$10:T10) -> 0 | BR10: =SUM($B$10:V10) -> 0 | BS10: =SUM($W$4:W10) -> 36.25 | BT10: =BR10+X10 -> 0 | BU10: =SUM($BT$4:BT10) -> 36.37
A11: Total ind | B11: =SUM(B4:B10) -> 2 | C11: =SUM(C4:C10) -> 0 | D11: =SUM(D4:D10) -> 5 | E11: =SUM(E4:E10) -> 9 | F11: =SUM(F4:F10) -> 4 | G11: =SUM(G4:G10) -> 0 | H11: =SUM(H4:H10) -> 0 | I11: =SUM(I4:I10) -> 3 | ... W11: =SUM(W4:W10) -> 36.25 | Y11: =SUM(Y4:Y10) -> 36.37 | Z11: How's your week? : | AD11: =TEXT(COUNTIF(AD4:AD10, ">0") / 7, "0%") -> 14%
A12: ratio | B12: =B11 -> 2 | C12: =C11 -> 0 | D12: =D11 -> 5 | E12: =E11 -> 9 | F12: =F11 -> 4 | G12: =G11 -> 0 | H12: =H11 -> 0 | I12: =I11 -> 3 | ... W12: =W11 -> 36.25
A13: Streaks | B13: {=IF(COUNTIF(AD4:AD10,0)=0, LOOKUP(2,1/(AD4:AD10<>""),AD4:AD10), MATCH(0,INDEX(AD4:AD10,MAX(ROW(AD4:AD10))-ROW(AD4:AD10)+1),0)-1 )} -> 0 | C13: {=IF(COUNTIF(AE4:AE10,0)=0, LOOKUP(2,1/(AE4:AE10<>""),AE4:AE10), MATCH(0,INDEX(AE4:AE10,MAX(ROW(AE4:AE10))-ROW(AE4:AE10)+1),0)-1 )} -> 0 | D13: {=IF(COUNTIF(AF4:AF10,0)=0, LOOKUP(2,1/(AF4:AF10<>""),AF4:AF10), MATCH(0,INDEX(AF4:AF10,MAX(ROW(AF4:AF10))-ROW(AF4:AF10)+1),0)-1 )} -> 0 | E13: {=IF(COUNTIF(AG4:AG10,0)=0, LOOKUP(2,1/(AG4:AG10<>""),AG4:AG10), MATCH(0,INDEX(AG4:AG10,MAX(ROW(AG4:AG10))-ROW(AG4:AG10)+1),0)-1 )} -> 0 | F13: {=IF(COUNTIF(AH4:AH10,0)=0, LOOKUP(2,1/(AH4:AH10<>""),AH4:AH10), MATCH(0,INDEX(AH4:AH10,MAX(ROW(AH4:AH10))-ROW(AH4:AH10)+1),0)-1 )} -> 0 | G13: {=IF(COUNTIF(AI4:AI10,0)=0, LOOKUP(2,1/(AI4:AI10<>""),AI4:AI10), MATCH(0,INDEX(AI4:AI10,MAX(ROW(AI4:AI10))-ROW(AI4:AI10)+1),0)-1 )} -> 0 | H13: {=IF(COUNTIF(AJ4:AJ10,0)=0, LOOKUP(2,1/(AJ4:AJ10<>""),AJ4:AJ10), MATCH(0,INDEX(AJ4:AJ10,MAX(ROW(AJ4:AJ10))-ROW(AJ4:AJ10)+1),0)-1 )} -> 0 | I13: {=IF(COUNTIF(AK4:AK10,0)=0, LOOKUP(2,1/(AK4:AK10<>""),AK4:AK10), MATCH(0,INDEX(AK4:AK10,MAX(ROW(AK4:AK10))-ROW(AK4:AK10)+1),0)-1 )} -> 0 | ... U13: {=IF(COUNTIF(AW4:AW10,0)=0, LOOKUP(2,1/(AW4:AW10<>""),AW4:AW10), MATCH(0,INDEX(AW4:AW10,MAX(ROW(AW4:AW10))-ROW(AW4:AW10)+1),0)-1 )} -> 0 | V13: {=IF(COUNTIF(Y4:Y10,0)=0, LOOKUP(2,1/(Y4:Y10<>""),Y4:Y10), MATCH(0,INDEX(Y4:Y10,MAX(ROW(Y4:Y10))-ROW(Y4:Y10)+1),0)-1 )} -> 0
A14: Cumulative | B14: =B12 -> 2 | C14: =C12 -> 0 | D14: =D12 -> 5 | E14: =E12 -> 9 | F14: =F12 -> 4 | G14: =G12 -> 0 | H14: =H12 -> 0 | I14: =I12 -> 3 | ... V14: =V12 -> 2 | W14: =SUM(W11) -> 36.25
A15: Consistency | B15: =COUNTIF(B4:B10, ">0") / 7 -> 0.14285714 | C15: =COUNTIF(C4:C10, ">0") / 7 -> 0 | D15: =COUNTIF(D4:D10, ">0") / 7 -> 0.14285714 | E15: =COUNTIF(E4:E10, ">0") / 7 -> 0.14285714 | F15: =COUNTIF(F4:F10, ">0") / 7 -> 0.14285714 | G15: =COUNTIF(G4:G10, ">0") / 7 -> 0 | H15: =COUNTIF(H4:H10, ">0") / 7 -> 0 | I15: =COUNTIF(I4:I10, ">0") / 7 -> 0.14285714 | ... O15: =COUNTIF(O4:O10, ">0") / 7 -> 0.14285714 | U15: negpos | V15: =SUMIF(B11:V11,"<0",B11:V11) -> -1 | W15: =SUM(C12:S12,V12) -> 35.25 | AY15: w2
AC16: W2 | AY16: @ 6am | AZ16: Bootup | BA16: Study | BB16: Gym | BC16: Work | BD16: Overtime | BE16: Cooking | BF16: D &H | BG16: Art | BH16: Chess | BI16: P & I | BJ16: Cleanliness | BK16: Hygeine | BL16: Resist | BM16: Binge | BN16: Help | BO16: Journal | BP16: Vibe | BQ16: by 11pm | BR16: Bonus/penalties | BS16: Total
A17: week2 | B17: =E3+1 -> 46034 | C17: =B17+6 -> 46040 | I17: Compete | J17: With | K17: Yourself | AC17: . | BS17: 0 | BT17: =BR17+X17 -> 0 | BU17: 0
A18: Mon | W18: =SUM(B18:V18) -> 0 | X18: =SUM(AD18:AW18)*0.1 -> 0 | Y18: =W18+X18 -> 0 | AB18: =W18+AB4 -> 36.25 | AC18: Mon | AD18: =IF(B18 > 0, IF(AD10> 0, AD10 + 1, 0.1), 0) -> 0 | AE18: =IF(C18 > 0, IF(AE10> 0, AE10 + 1, 0.1), 0) -> 0 | AF18: =IF(D18 > 0, IF(AF10> 0, AF10 + 1, 0.1), 0) -> 0 | AG18: =IF(E18 > 0, IF(AG10> 0, AG10 + 1, 0.1), 0) -> 0 | AH18: =IF(F18 > 0, IF(AH10> 0, AH10 + 1, 0.1), 0) -> 0 | AI18: =IF(G18 > 0, IF(AI10> 0, AI10 + 1, 0.1), 0) -> 0 | AJ18: =IF(H18 > 0, IF(AJ10> 0, AJ10 + 1, 0.1), 0) -> 0 | AK18: =IF(I18 > 0, IF(AK10> 0, AK10 + 1, 0.1), 0) -> 0 | ... AW18: =IF(U18 > 0, IF(AW10> 0, AW10 + 1, 0.1), 0) -> 0 | AY18: =SUM($B$18:B18) -> 0 | AZ18: =SUM($B$18:C18) -> 0 | BA18: =SUM($B$18:D18) -> 0 | BB18: =SUM($B$18:E18) -> 0 | BC18: =SUM($B$18:F18) -> 0 | BD18: =SUM($B$18:G18) -> 0 | BE18: =SUM($B$18:H18) -> 0 | BF18: =SUM($B$18:I18) -> 0 | ... BJ18: =SUM($B$18:M18) -> 0 | BK18: =SUM($B$18:Q18) -> 0 | BL18: =SUM($B$18:N18) -> 0 | BM18: =SUM($B$18:O18) -> 0 | BN18: =SUM($B$18:P18) -> 0 | BO18: =SUM($B$18:R18) -> 0 | BP18: =SUM($B$18:S18) -> 0 | BQ18: =SUM($B$18:T18) -> 0 | BR18: =SUM($B$18:V18) -> 0 | BS18: =SUM($BR$18:BR18) -> 0 | BT18: =BR18+X18 -> 0 | BU18: =SUM($BT$18:BT18) -> 0
A19: Tue | W19: =SUM(B19:U19) -> 0 | X19: =SUM(AD19:AW19)*0.1 -> 0 | Y19: =W19+X19 -> 0 | AB19: =AB5+W19 -> 0 | AC19: Tue | AD19: =IF(B19 > 0, IF(AD18 > 0, AD18 + 1, 0.1), 0) -> 0 | AE19: =IF(C19 > 0, IF(AE18 > 0, AE18 + 1, 0.1), 0) -> 0 | AF19: =IF(D19 > 0, IF(AF18 > 0, AF18 + 1, 0.1), 0) -> 0 | AG19: =IF(E19 > 0, IF(AG18 > 0, AG18 + 1, 0.1), 0) -> 0 | AH19: =IF(F19 > 0, IF(AH18 > 0, AH18 + 1, 0.1), 0) -> 0 | AI19: =IF(G19 > 0, IF(AI18 > 0, AI18 + 1, 0.1), 0) -> 0 | AJ19: =IF(H19 > 0, IF(AJ18 > 0, AJ18 + 1, 0.1), 0) -> 0 | AK19: =IF(I19 > 0, IF(AK18 > 0, AK18 + 1, 0.1), 0) -> 0 | ... AT19: =IF(R19 > 0, IF(AT18 > 0, AT18 + 1, 0.1), 0) -> 0 | AU19: =IF(S19 > 0, IF(AU11> 0, AU11 + 1, 0.1), 0) -> 0 | AV19: =IF(T19 > 0, IF(AV18 > 0, AV18 + 1, 0.1), 0) -> 0 | AW19: =IF(U19 > 0, IF(AW18 > 0, AW18 + 1, 0.1), 0) -> 0 | AY19: =SUM($B$19:B19) -> 0 | AZ19: =SUM($B$19:C19) -> 0 | BA19: =SUM($B$19:D19) -> 0 | BB19: =SUM($B$19:E19) -> 0 | BC19: =SUM($B$19:F19) -> 0 | BD19: =SUM($B$19:G19) -> 0 | BE19: =SUM($B$19:H19) -> 0 | BF19: =SUM($B$19:I19) -> 0 | ... BJ19: =SUM($B$19:M19) -> 0 | BK19: =SUM($B$19:Q19) -> 0 | BL19: =SUM($B$19:N19) -> 0 | BM19: =SUM($B$19:O19) -> 0 | BN19: =SUM($B$19:P19) -> 0 | BO19: =SUM($B$19:R19) -> 0 | BP19: =SUM($B$19:S19) -> 0 | BQ19: =SUM($B$19:T19) -> 0 | BR19: =SUM($B$19:V19) -> 0 | BS19: =SUM($BR$18:BR19) -> 0 | BT19: =BR19+X19 -> 0 | BU19: =SUM($BT$18:BT19) -> 0
A20: Wed | W20: =SUM(B20:U20) -> 0 | X20: =SUM(AD20:AW20)*0.1 -> 0 | Y20: =W20+X20 -> 0 | AB20: =AB6+W20 -> 0 | AC20: Wed | AD20: =IF(B20 > 0, IF(AD19 > 0, AD19 + 1, 0.1), 0) -> 0 | AE20: =IF(C20 > 0, IF(AE19 > 0, AE19 + 1, 0.1), 0) -> 0 | AF20: =IF(D20 > 0, IF(AF19 > 0, AF19 + 1, 0.1), 0) -> 0 | AG20: =IF(E20 > 0, IF(AG19 > 0, AG19 + 1, 0.1), 0) -> 0 | AH20: =IF(F20 > 0, IF(AH19 > 0, AH19 + 1, 0.1), 0) -> 0 | AI20: =IF(G20 > 0, IF(AI19 > 0, AI19 + 1, 0.1), 0) -> 0 | AJ20: =IF(H20 > 0, IF(AJ19 > 0, AJ19 + 1, 0.1), 0) -> 0 | AK20: =IF(I20 > 0, IF(AK19 > 0, AK19 + 1, 0.1), 0) -> 0 | ... AT20: =IF(R20 > 0, IF(AT19 > 0, AT19 + 1, 0.1), 0) -> 0 | AU20: =IF(S20 > 0, IF(AU12> 0, AU12 + 1, 0.1), 0) -> 0 | AV20: =IF(T20 > 0, IF(AV19 > 0, AV19 + 1, 0.1), 0) -> 0 | AW20: =IF(U20 > 0, IF(AW19 > 0, AW19 + 1, 0.1), 0) -> 0 | AY20: =SUM($B$20:B20) -> 0 | AZ20: =SUM($B$20:C20) -> 0 | BA20: =SUM($B$20:D20) -> 0 | BB20: =SUM($B$20:E20) -> 0 | BC20: =SUM($B$20:F20) -> 0 | BD20: =SUM($B$20:G20) -> 0 | BE20: =SUM($B$20:H20) -> 0 | BF20: =SUM($B$20:I20) -> 0 | ... BJ20: =SUM($B$20:M20) -> 0 | BK20: =SUM($B$20:Q20) -> 0 | BL20: =SUM($B$20:N20) -> 0 | BM20: =SUM($B$20:O20) -> 0 | BN20: =SUM($B$20:P20) -> 0 | BO20: =SUM($B$20:R20) -> 0 | BP20: =SUM($B$20:S20) -> 0 | BQ20: =SUM($B$20:T20) -> 0 | BR20: =SUM($B$20:V20) -> 0 | BS20: =SUM($BR$18:BR20) -> 0 | BT20: =BR20+X20 -> 0 | BU20: =SUM($BT$18:BT20) -> 0
A21: Thu | W21: =SUM(B21:U21) -> 0 | X21: =SUM(AD21:AW21)*0.1 -> 0 | Y21: =W21+X21 -> 0 | AB21: =AB7+W21 -> 0 | AC21: Thu | AD21: =IF(B21 > 0, IF(AD20 > 0, AD20 + 1, 0.1), 0) -> 0 | AE21: =IF(C21 > 0, IF(AE20 > 0, AE20 + 1, 0.1), 0) -> 0 | AF21: =IF(D21 > 0, IF(AF20 > 0, AF20 + 1, 0.1), 0) -> 0 | AG21: =IF(E21 > 0, IF(AG20 > 0, AG20 + 1, 0.1), 0) -> 0 | AH21: =IF(F21 > 0, IF(AH20 > 0, AH20 + 1, 0.1), 0) -> 0 | AI21: =IF(G21 > 0, IF(AI20 > 0, AI20 + 1, 0.1), 0) -> 0 | AJ21: =IF(H21 > 0, IF(AJ20 > 0, AJ20 + 1, 0.1), 0) -> 0 | AK21: =IF(I21 > 0, IF(AK20 > 0, AK20 + 1, 0.1), 0) -> 0 | ... AT21: =IF(R21 > 0, IF(AT20 > 0, AT20 + 1, 0.1), 0) -> 0 | AU21: =IF(S21 > 0, IF(AU13> 0, AU13 + 1, 0.1), 0) -> 0 | AV21: =IF(T21 > 0, IF(AV20 > 0, AV20 + 1, 0.1), 0) -> 0 | AW21: =IF(U21 > 0, IF(AW20 > 0, AW20 + 1, 0.1), 0) -> 0 | AY21: =SUM($B$21:B21) -> 0 | AZ21: =SUM($B$21:C21) -> 0 | BA21: =SUM($B$21:D21) -> 0 | BB21: =SUM($B$21:E21) -> 0 | BC21: =SUM($B$21:F21) -> 0 | BD21: =SUM($B$21:G21) -> 0 | BE21: =SUM($B$21:H21) -> 0 | BF21: =SUM($B$21:I21) -> 0 | ... BJ21: =SUM($B$21:M21) -> 0 | BK21: =SUM($B$21:Q21) -> 0 | BL21: =SUM($B$21:N21) -> 0 | BM21: =SUM($B$21:O21) -> 0 | BN21: =SUM($B$21:P21) -> 0 | BO21: =SUM($B$21:R21) -> 0 | BP21: =SUM($B$21:S21) -> 0 | BQ21: =SUM($B$21:T21) -> 0 | BR21: =SUM($B$21:V21) -> 0 | BS21: =SUM($BR$18:BR21) -> 0 | BT21: =BR21+X21 -> 0 | BU21: =SUM($BT$18:BT21) -> 0
A22: Fri | W22: =SUM(B22:U22) -> 0 | X22: =SUM(AD22:AW22)*0.1 -> 0 | Y22: =W22+X22 -> 0 | AB22: =W22+AB8 -> 0 | AC22: Fri | AD22: =IF(B22 > 0, IF(AD21 > 0, AD21 + 1, 0.1), 0) -> 0 | AE22: =IF(C22 > 0, IF(AE21 > 0, AE21 + 1, 0.1), 0) -> 0 | AF22: =IF(D22 > 0, IF(AF21 > 0, AF21 + 1, 0.1), 0) -> 0 | AG22: =IF(E22 > 0, IF(AG21 > 0, AG21 + 1, 0.1), 0) -> 0 | AH22: =IF(F22 > 0, IF(AH21 > 0, AH21 + 1, 0.1), 0) -> 0 | AI22: =IF(G22 > 0, IF(AI21 > 0, AI21 + 1, 0.1), 0) -> 0 | AJ22: =IF(H22 > 0, IF(AJ21 > 0, AJ21 + 1, 0.1), 0) -> 0 | AK22: =IF(I22 > 0, IF(AK21 > 0, AK21 + 1, 0.1), 0) -> 0 | ... AT22: =IF(R22 > 0, IF(AT21 > 0, AT21 + 1, 0.1), 0) -> 0 | AU22: =IF(S22 > 0, IF(AU14> 0, AU14 + 1, 0.1), 0) -> 0 | AV22: =IF(T22 > 0, IF(AV21 > 0, AV21 + 1, 0.1), 0) -> 0 | AW22: =IF(U22 > 0, IF(AW21 > 0, AW21 + 1, 0.1), 0) -> 0 | AY22: =SUM($B$22:B22) -> 0 | AZ22: =SUM($B$22:C22) -> 0 | BA22: =SUM($B$22:D22) -> 0 | BB22: =SUM($B$22:E22) -> 0 | BC22: =SUM($B$22:F22) -> 0 | BD22: =SUM($B$22:G22) -> 0 | BE22: =SUM($B$22:H22) -> 0 | BF22: =SUM($B$22:I22) -> 0 | ... BJ22: =SUM($B$22:M22) -> 0 | BK22: =SUM($B$22:Q22) -> 0 | BL22: =SUM($B$22:N22) -> 0 | BM22: =SUM($B$22:O22) -> 0 | BN22: =SUM($B$22:P22) -> 0 | BO22: =SUM($B$22:R22) -> 0 | BP22: =SUM($B$22:S22) -> 0 | BQ22: =SUM($B$22:T22) -> 0 | BR22: =SUM($B$22:V22) -> 0 | BS22: =SUM($BR$18:BR22) -> 0 | BT22: =BR22+X22 -> 0 | BU22: =SUM($BT$18:BT22) -> 0
A23: Sat | W23: =SUM(B23:U23) -> 0 | X23: =SUM(AD23:AW23)*0.1 -> 0 | Y23: =W23+X23 -> 0 | AB23: =AB9+W23 -> 0 | AC23: Sat | AD23: =IF(B23 > 0, IF(AD22 > 0, AD22 + 1, 0.1), 0) -> 0 | AE23: =IF(C23 > 0, IF(AE22 > 0, AE22 + 1, 0.1), 0) -> 0 | AF23: =IF(D23 > 0, IF(AF22 > 0, AF22 + 1, 0.1), 0) -> 0 | AG23: =IF(E23 > 0, IF(AG22 > 0, AG22 + 1, 0.1), 0) -> 0 | AH23: =IF(F23 > 0, IF(AH22 > 0, AH22 + 1, 0.1), 0) -> 0 | AI23: =IF(G23 > 0, IF(AI22 > 0, AI22 + 1, 0.1), 0) -> 0 | AJ23: =IF(H23 > 0, IF(AJ22 > 0, AJ22 + 1, 0.1), 0) -> 0 | AK23: =IF(I23 > 0, IF(AK22 > 0, AK22 + 1, 0.1), 0) -> 0 | ... AT23: =IF(R23 > 0, IF(AT22 > 0, AT22 + 1, 0.1), 0) -> 0 | AU23: =IF(S23 > 0, IF(AU15> 0, AU15 + 1, 0.1), 0) -> 0 | AV23: =IF(T23 > 0, IF(AV22 > 0, AV22 + 1, 0.1), 0) -> 0 | AW23: =IF(U23 > 0, IF(AW22 > 0, AW22 + 1, 0.1), 0) -> 0 | AY23: =SUM($B$23:B23) -> 0 | AZ23: =SUM($B$23:C23) -> 0 | BA23: =SUM($B$23:D23) -> 0 | BB23: =SUM($B$23:E23) -> 0 | BC23: =SUM($B$23:F23) -> 0 | BD23: =SUM($B$23:G23) -> 0 | BE23: =SUM($B$23:H23) -> 0 | BF23: =SUM($B$23:I23) -> 0 | ... BJ23: =SUM($B$23:M23) -> 0 | BK23: =SUM($B$23:Q23) -> 0 | BL23: =SUM($B$23:N23) -> 0 | BM23: =SUM($B$23:O23) -> 0 | BN23: =SUM($B$23:P23) -> 0 | BO23: =SUM($B$23:R23) -> 0 | BP23: =SUM($B$23:S23) -> 0 | BQ23: =SUM($B$23:T23) -> 0 | BR23: =SUM($B$23:V23) -> 0 | BS23: =SUM($BR$18:BR23) -> 0 | BT23: =BR23+X23 -> 0 | BU23: =SUM($BT$18:BT23) -> 0
A24: Sun | W24: =SUM(B24:U24) -> 0 | X24: =SUM(AD24:AW24)*0.1 -> 0 | Y24: =W24+X24 -> 0 | AB24: =AB10+W24 -> 0 | AC24: Sun | AD24: =IF(B24 > 0, IF(AD23 > 0, AD23 + 1, 0.1), 0) -> 0 | AE24: =IF(C24 > 0, IF(AE23 > 0, AE23 + 1, 0.1), 0) -> 0 | AF24: =IF(D24 > 0, IF(AF23 > 0, AF23 + 1, 0.1), 0) -> 0 | AG24: =IF(E24 > 0, IF(AG23 > 0, AG23 + 1, 0.1), 0) -> 0 | AH24: =IF(F24 > 0, IF(AH23 > 0, AH23 + 1, 0.1), 0) -> 0 | AI24: =IF(G24 > 0, IF(AI23 > 0, AI23 + 1, 0.1), 0) -> 0 | AJ24: =IF(H24 > 0, IF(AJ23 > 0, AJ23 + 1, 0.1), 0) -> 0 | AK24: =IF(I24 > 0, IF(AK23 > 0, AK23 + 1, 0.1), 0) -> 0 | ... AT24: =IF(R24 > 0, IF(AT23 > 0, AT23 + 1, 0.1), 0) -> 0 | AU24: =IF(S24 > 0, IF(AU16> 0, AU16 + 1, 0.1), 0) -> 0 | AV24: =IF(T24 > 0, IF(AV23 > 0, AV23 + 1, 0.1), 0) -> 0 | AW24: =IF(U24 > 0, IF(AW23 > 0, AW23 + 1, 0.1), 0) -> 0 | AY24: =SUM($B$24:B24) -> 0 | AZ24: =SUM($B$24:C24) -> 0 | BA24: =SUM($B$24:D24) -> 0 | BB24: =SUM($B$24:E24) -> 0 | BC24: =SUM($B$24:F24) -> 0 | BD24: =SUM($B$24:G24) -> 0 | BE24: =SUM($B$24:H24) -> 0 | BF24: =SUM($B$24:I24) -> 0 | ... BJ24: =SUM($B$24:M24) -> 0 | BK24: =SUM($B$24:Q24) -> 0 | BL24: =SUM($B$24:N24) -> 0 | BM24: =SUM($B$24:O24) -> 0 | BN24: =SUM($B$24:P24) -> 0 | BO24: =SUM($B$24:R24) -> 0 | BP24: =SUM($B$24:S24) -> 0 | BQ24: =SUM($B$24:T24) -> 0 | BR24: =SUM($B$24:V24) -> 0 | BS24: =SUM($BR$18:BR24) -> 0 | BT24: =BR24+X24 -> 0 | BU24: =SUM($BT$18:BT24) -> 0
A25: Total ind | B25: =SUM(B18:B24) -> 0 | C25: =SUM(C18:C24) -> 0 | D25: =SUM(D18:D24) -> 0 | E25: =SUM(E18:E24) -> 0 | F25: =SUM(F18:F24) -> 0 | G25: =SUM(G18:G24) -> 0 | H25: =SUM(H18:H24) -> 0 | I25: =SUM(I18:I24) -> 0 | ... W25: =SUM(W18:W24) -> 0 | Z25: How's your week?: | AD25: =MAX(AD18:AD24) -> 0 | AE25: =MAX(AE18:AE24) -> 0 | AF25: =MAX(AF18:AF24) -> 0 | AG25: =MAX(AG18:AG24) -> 0 | AH25: =MAX(AH18:AH24) -> 0 | AI25: =MAX(AI18:AI24) -> 0 | AJ25: =MAX(AJ18:AJ24) -> 0 | AK25: =MAX(AK18:AK24) -> 0 | ... AW25: =MAX(AW18:AW24) -> 0
A26: Ratio | B26: =B25-B11 -> -2 | C26: =C25-C11 -> 0 | D26: =D25-D11 -> -5 | E26: =E25-E11 -> -9 | F26: =F25-F11 -> -4 | G26: =G25-G11 -> 0 | H26: =H25-H11 -> 0 | I26: =I25-I11 -> -3 | ... W26: =W25-W11 -> -36.25
A27: Streaks | B27: {=IF(COUNTIF(AD18:AD24,0)=0, LOOKUP(2,1/(AD18:AD24<>""),AD18:AD24), MATCH(0,INDEX(AD18:AD24,MAX(ROW(AD18:AD24))-ROW(AD18:AD24)+1),0)-1 )} -> 0 | C27: {=IF(COUNTIF(AE18:AE24,0)=0, LOOKUP(2,1/(AE18:AE24<>""),AE18:AE24), MATCH(0,INDEX(AE18:AE24,MAX(ROW(AE18:AE24))-ROW(AE18:AE24)+1),0)-1 )} -> 0 | D27: {=IF(COUNTIF(AF18:AF24,0)=0, LOOKUP(2,1/(AF18:AF24<>""),AF18:AF24), MATCH(0,INDEX(AF18:AF24,MAX(ROW(AF18:AF24))-ROW(AF18:AF24)+1),0)-1 )} -> 0 | E27: {=IF(COUNTIF(AG18:AG24,0)=0, LOOKUP(2,1/(AG18:AG24<>""),AG18:AG24), MATCH(0,INDEX(AG18:AG24,MAX(ROW(AG18:AG24))-ROW(AG18:AG24)+1),0)-1 )} -> 0 | F27: {=IF(COUNTIF(AH18:AH24,0)=0, LOOKUP(2,1/(AH18:AH24<>""),AH18:AH24), MATCH(0,INDEX(AH18:AH24,MAX(ROW(AH18:AH24))-ROW(AH18:AH24)+1),0)-1 )} -> 0 | G27: {=IF(COUNTIF(AI18:AI24,0)=0, LOOKUP(2,1/(AI18:AI24<>""),AI18:AI24), MATCH(0,INDEX(AI18:AI24,MAX(ROW(AI18:AI24))-ROW(AI18:AI24)+1),0)-1 )} -> 0 | H27: {=IF(COUNTIF(AJ18:AJ24,0)=0, LOOKUP(2,1/(AJ18:AJ24<>""),AJ18:AJ24), MATCH(0,INDEX(AJ18:AJ24,MAX(ROW(AJ18:AJ24))-ROW(AJ18:AJ24)+1),0)-1 )} -> 0 | I27: {=IF(COUNTIF(AK18:AK24,0)=0, LOOKUP(2,1/(AK18:AK24<>""),AK18:AK24), MATCH(0,INDEX(AK18:AK24,MAX(ROW(AK18:AK24))-ROW(AK18:AK24)+1),0)-1 )} -> 0 | ... U27: {=IF(COUNTIF(AW18:AW24,0)=0, LOOKUP(2,1/(AW18:AW24<>""),AW18:AW24), MATCH(0,INDEX(AW18:AW24,MAX(ROW(AW18:AW24))-ROW(AW18:AW24)+1),0)-1 )} -> 0 | V27: {=IF(COUNTIF(Y18:Y24,0)=0, LOOKUP(2,1/(Y18:Y24<>""),Y18:Y24), MATCH(0,INDEX(Y18:Y24,MAX(ROW(Y18:Y24))-ROW(Y18:Y24)+1),0)-1 )} -> 0
A28: Cumulative | B28: =B25+B14 -> 2 | C28: =C25+C14 -> 0 | D28: =D25+D14 -> 5 | E28: =E25+E14 -> 9 | F28: =F25+F14 -> 4 | G28: =G25+G14 -> 0 | H28: =H25+H14 -> 0 | I28: =I25+I14 -> 3 | ... V28: =V25+V14 -> 2 | W28: =SUM(W14,W25) -> 36.25 | Y28: =SUM(Y18:Y24) -> 0
A29: Consistency | B29: =(COUNTIF(B4:B10, ">0") + COUNTIF(B18:B24, ">0")) / 14 -> 0.071428571 | C29: =(COUNTIF(C4:C10, ">0") + COUNTIF(C18:C24, ">0")) / 14 -> 0 | D29: =(COUNTIF(D4:D10, ">0") + COUNTIF(D18:D24, ">0")) / 14 -> 0.071428571 | E29: =(COUNTIF(E4:E10, ">0") + COUNTIF(E18:E24, ">0")) / 14 -> 0.071428571 | F29: =(COUNTIF(F4:F10, ">0") + COUNTIF(F18:F24, ">0")) / 14 -> 0.071428571 | G29: =(COUNTIF(G4:G10, ">0") + COUNTIF(G18:G24, ">0")) / 14 -> 0 | H29: =(COUNTIF(H4:H10, ">0") + COUNTIF(H18:H24, ">0")) / 14 -> 0 | I29: =(COUNTIF(I4:I10, ">0") + COUNTIF(I18:I24, ">0")) / 14 -> 0.071428571 | ... O29: =(COUNTIF(O4:O10, ">0") + COUNTIF(O18:O24, ">0")) / 14 -> 0.071428571 | U29: Negpos | V29: =SUMIF(B25:V25,"<0",B25:V25) -> 0 | W29: =SUMIF(B25:V25,">0",B25:V25) -> 0
AY30: w3
A31: week3 | B31: =C17+1 -> 46041 | C31: =B31+6 -> 46047 | G31: its | H31: an | I31: observation | J31: before | K31: competion. | AC31: W3 | AY31: @ 6am | AZ31: Bootup | BA31: Study | BB31: Gym | BC31: Work | BD31: Overtime | BE31: Cooking | BF31: D &H | BG31: Art | BH31: Chess | BI31: P & I | BJ31: Cleanliness | BK31: Hygeine | BL31: Resist | BM31: Binge | BN31: Help | BO31: Journal | BP31: Vibe | BQ31: by 11pm | BR31: Bonus/penalties | BS31: 0 | BU31: 0
A32: Mon | W32: =SUM(B32:V32) -> 0 | X32: =SUM(AD32:AW32)*0.1 -> 0 | Y32: =W32+X32 -> 0 | AB32: =W32+AB18 -> 36.25 | AC32: Mon | AD32: =IF(B32 > 0, IF(AD24> 0, AD24 + 1, 0.1), 0) -> 0 | AE32: =IF(C32 > 0, IF(AE24> 0, AE24 + 1, 0.1), 0) -> 0 | AF32: =IF(D32 > 0, IF(AF24> 0, AF24 + 1, 0.1), 0) -> 0 | AG32: =IF(E32 > 0, IF(AG24> 0, AG24 + 1, 0.1), 0) -> 0 | AH32: =IF(F32 > 0, IF(AH24> 0, AH24 + 1, 0.1), 0) -> 0 | AI32: =IF(G32 > 0, IF(AI24> 0, AI24 + 1, 0.1), 0) -> 0 | AJ32: =IF(H32 > 0, IF(AJ24> 0, AJ24 + 1, 0.1), 0) -> 0 | AK32: =IF(I32 > 0, IF(AK24> 0, AK24 + 1, 0.1), 0) -> 0 | ... AW32: =IF(U32 > 0, IF(AW24> 0, AW24 + 1, 0.1), 0) -> 0 | AY32: =SUM($B$32:B32) -> 0 | AZ32: =SUM($B$32:C32) -> 0 | BA32: =SUM($B$32:D32) -> 0 | BB32: =SUM($B$32:E32) -> 0 | BC32: =SUM($B$32:F32) -> 0 | BD32: =SUM($B$32:G32) -> 0 | BE32: =SUM($B$32:H32) -> 0 | BF32: =SUM($B$32:I32) -> 0 | ... BJ32: =SUM($B$32:M32) -> 0 | BK32: =SUM($B$32:Q32) -> 0 | BL32: =SUM($B$32:N32) -> 0 | BM32: =SUM($B$32:O32) -> 0 | BN32: =SUM($B$32:P32) -> 0 | BO32: =SUM($B$32:R32) -> 0 | BP32: =SUM($B$32:S32) -> 0 | BQ32: =SUM($B$32:T32) -> 0 | BR32: =SUM($B$32:V32) -> 0 | BS32: =SUM($BR$32:BR32) -> 0 | BT32: =BR32+X32 -> 0 | BU32: =SUM($BT$32:BT32) -> 0
A33: Tue | W33: =SUM(B33:V33) -> 0 | X33: =SUM(AD33:AW33)*0.1 -> 0 | Y33: =W33+X33 -> 0 | AB33: =AB19+W33 -> 0 | AC33: Tue | AD33: =IF(B33 > 0, IF(AD32 > 0, AD32 + 1, 0.1), 0) -> 0 | AE33: =IF(C33 > 0, IF(AE32 > 0, AE32 + 1, 0.1), 0) -> 0 | AF33: =IF(D33 > 0, IF(AF32 > 0, AF32 + 1, 0.1), 0) -> 0 | AG33: =IF(E33 > 0, IF(AG32 > 0, AG32 + 1, 0.1), 0) -> 0 | AH33: =IF(F33 > 0, IF(AH32 > 0, AH32 + 1, 0.1), 0) -> 0 | AI33: =IF(G33 > 0, IF(AI32 > 0, AI32 + 1, 0.1), 0) -> 0 | AJ33: =IF(H33 > 0, IF(AJ32 > 0, AJ32 + 1, 0.1), 0) -> 0 | AK33: =IF(I33 > 0, IF(AK32 > 0, AK32 + 1, 0.1), 0) -> 0 | ... AT33: =IF(R33 > 0, IF(AT32 > 0, AT32 + 1, 0.1), 0) -> 0 | AU33: =IF(S33 > 0, IF(AU25> 0, AU25 + 1, 0.1), 0) -> 0 | AV33: =IF(T33 > 0, IF(AV32 > 0, AV32 + 1, 0.1), 0) -> 0 | AW33: =IF(U33 > 0, IF(AW32 > 0, AW32 + 1, 0.1), 0) -> 0 | AY33: =SUM($B$33:B33) -> 0 | AZ33: =SUM($B$33:C33) -> 0 | BA33: =SUM($B$33:D33) -> 0 | BB33: =SUM($B$33:E33) -> 0 | BC33: =SUM($B$33:F33) -> 0 | BD33: =SUM($B$33:G33) -> 0 | BE33: =SUM($B$33:H33) -> 0 | BF33: =SUM($B$33:I33) -> 0 | ... BJ33: =SUM($B$33:M33) -> 0 | BK33: =SUM($B$33:Q33) -> 0 | BL33: =SUM($B$33:N33) -> 0 | BM33: =SUM($B$33:O33) -> 0 | BN33: =SUM($B$33:P33) -> 0 | BO33: =SUM($B$33:R33) -> 0 | BP33: =SUM($B$33:S33) -> 0 | BQ33: =SUM($B$33:T33) -> 0 | BR33: =SUM($B$33:V33) -> 0 | BS33: =SUM($BR$32:BR33) -> 0 | BT33: =BR33+X33 -> 0 | BU33: =SUM($BT$32:BT33) -> 0
A34: Wed | W34: =SUM(B34:V34) -> 0 | X34: =SUM(AD34:AW34)*0.1 -> 0 | Y34: =W34+X34 -> 0 | AB34: =AB20+W34 -> 0 | AC34: Wed | AD34: =IF(B34 > 0, IF(AD33 > 0, AD33 + 1, 0.1), 0) -> 0 | AE34: =IF(C34 > 0, IF(AE33 > 0, AE33 + 1, 0.1), 0) -> 0 | AF34: =IF(D34 > 0, IF(AF33 > 0, AF33 + 1, 0.1), 0) -> 0 | AG34: =IF(E34 > 0, IF(AG33 > 0, AG33 + 1, 0.1), 0) -> 0 | AH34: =IF(F34 > 0, IF(AH33 > 0, AH33 + 1, 0.1), 0) -> 0 | AI34: =IF(G34 > 0, IF(AI33 > 0, AI33 + 1, 0.1), 0) -> 0 | AJ34: =IF(H34 > 0, IF(AJ33 > 0, AJ33 + 1, 0.1), 0) -> 0 | AK34: =IF(I34 > 0, IF(AK33 > 0, AK33 + 1, 0.1), 0) -> 0 | ... AT34: =IF(R34 > 0, IF(AT33 > 0, AT33 + 1, 0.1), 0) -> 0 | AU34: =IF(S34 > 0, IF(AU26> 0, AU26 + 1, 0.1), 0) -> 0 | AV34: =IF(T34 > 0, IF(AV33 > 0, AV33 + 1, 0.1), 0) -> 0 | AW34: =IF(U34 > 0, IF(AW33 > 0, AW33 + 1, 0.1), 0) -> 0 | AY34: =SUM($B$34:B34) -> 0 | AZ34: =SUM($B$34:C34) -> 0 | BA34: =SUM($B$34:D34) -> 0 | BB34: =SUM($B$34:E34) -> 0 | BC34: =SUM($B$34:F34) -> 0 | BD34: =SUM($B$34:G34) -> 0 | BE34: =SUM($B$34:H34) -> 0 | BF34: =SUM($B$34:I34) -> 0 | ... BJ34: =SUM($B$34:M34) -> 0 | BK34: =SUM($B$34:Q34) -> 0 | BL34: =SUM($B$34:N34) -> 0 | BM34: =SUM($B$34:O34) -> 0 | BN34: =SUM($B$34:P34) -> 0 | BO34: =SUM($B$34:R34) -> 0 | BP34: =SUM($B$34:S34) -> 0 | BQ34: =SUM($B$34:T34) -> 0 | BR34: =SUM($B$34:V34) -> 0 | BS34: =SUM($BR$32:BR34) -> 0 | BT34: =BR34+X34 -> 0 | BU34: =SUM($BT$32:BT34) -> 0
A35: Thu | W35: =SUM(B35:V35) -> 0 | X35: =SUM(AD35:AW35)*0.1 -> 0 | Y35: =W35+X35 -> 0 | AB35: =AB21+W35 -> 0 | AC35: Thu | AD35: =IF(B35 > 0, IF(AD34 > 0, AD34 + 1, 0.1), 0) -> 0 | AE35: =IF(C35 > 0, IF(AE34 > 0, AE34 + 1, 0.1), 0) -> 0 | AF35: =IF(D35 > 0, IF(AF34 > 0, AF34 + 1, 0.1), 0) -> 0 | AG35: =IF(E35 > 0, IF(AG34 > 0, AG34 + 1, 0.1), 0) -> 0 | AH35: =IF(F35 > 0, IF(AH34 > 0, AH34 + 1, 0.1), 0) -> 0 | AI35: =IF(G35 > 0, IF(AI34 > 0, AI34 + 1, 0.1), 0) -> 0 | AJ35: =IF(H35 > 0, IF(AJ34 > 0, AJ34 + 1, 0.1), 0) -> 0 | AK35: =IF(I35 > 0, IF(AK34 > 0, AK34 + 1, 0.1), 0) -> 0 | ... AT35: =IF(R35 > 0, IF(AT34 > 0, AT34 + 1, 0.1), 0) -> 0 | AU35: =IF(S35 > 0, IF(AU27> 0, AU27 + 1, 0.1), 0) -> 0 | AV35: =IF(T35 > 0, IF(AV34 > 0, AV34 + 1, 0.1), 0) -> 0 | AW35: =IF(U35 > 0, IF(AW34 > 0, AW34 + 1, 0.1), 0) -> 0 | AY35: =SUM($B$35:B35) -> 0 | AZ35: =SUM($B$35:C35) -> 0 | BA35: =SUM($B$35:D35) -> 0 | BB35: =SUM($B$35:E35) -> 0 | BC35: =SUM($B$35:F35) -> 0 | BD35: =SUM($B$35:G35) -> 0 | BE35: =SUM($B$35:H35) -> 0 | BF35: =SUM($B$35:I35) -> 0 | ... BJ35: =SUM($B$35:M35) -> 0 | BK35: =SUM($B$35:Q35) -> 0 | BL35: =SUM($B$35:N35) -> 0 | BM35: =SUM($B$35:O35) -> 0 | BN35: =SUM($B$35:P35) -> 0 | BO35: =SUM($B$35:R35) -> 0 | BP35: =SUM($B$35:S35) -> 0 | BQ35: =SUM($B$35:T35) -> 0 | BR35: =SUM($B$35:V35) -> 0 | BS35: =SUM($BR$32:BR35) -> 0 | BT35: =BR35+X35 -> 0 | BU35: =SUM($BT$32:BT35) -> 0
A36: Fri | W36: =SUM(B36:V36) -> 0 | X36: =SUM(AD36:AW36)*0.1 -> 0 | Y36: =W36+X36 -> 0 | AB36: =AB22+W36 -> 0 | AC36: Fri | AD36: =IF(B36 > 0, IF(AD35 > 0, AD35 + 1, 0.1), 0) -> 0 | AE36: =IF(C36 > 0, IF(AE35 > 0, AE35 + 1, 0.1), 0) -> 0 | AF36: =IF(D36 > 0, IF(AF35 > 0, AF35 + 1, 0.1), 0) -> 0 | AG36: =IF(E36 > 0, IF(AG35 > 0, AG35 + 1, 0.1), 0) -> 0 | AH36: =IF(F36 > 0, IF(AH35 > 0, AH35 + 1, 0.1), 0) -> 0 | AI36: =IF(G36 > 0, IF(AI35 > 0, AI35 + 1, 0.1), 0) -> 0 | AJ36: =IF(H36 > 0, IF(AJ35 > 0, AJ35 + 1, 0.1), 0) -> 0 | AK36: =IF(I36 > 0, IF(AK35 > 0, AK35 + 1, 0.1), 0) -> 0 | ... AT36: =IF(R36 > 0, IF(AT35 > 0, AT35 + 1, 0.1), 0) -> 0 | AU36: =IF(S36 > 0, IF(AU28> 0, AU28 + 1, 0.1), 0) -> 0 | AV36: =IF(T36 > 0, IF(AV35 > 0, AV35 + 1, 0.1), 0) -> 0 | AW36: =IF(U36 > 0, IF(AW35 > 0, AW35 + 1, 0.1), 0) -> 0 | AY36: =SUM($B$36:B36) -> 0 | AZ36: =SUM($B$36:C36) -> 0 | BA36: =SUM($B$36:D36) -> 0 | BB36: =SUM($B$36:E36) -> 0 | BC36: =SUM($B$36:F36) -> 0 | BD36: =SUM($B$36:G36) -> 0 | BE36: =SUM($B$36:H36) -> 0 | BF36: =SUM($B$36:I36) -> 0 | ... BJ36: =SUM($B$36:M36) -> 0 | BK36: =SUM($B$36:Q36) -> 0 | BL36: =SUM($B$36:N36) -> 0 | BM36: =SUM($B$36:O36) -> 0 | BN36: =SUM($B$36:P36) -> 0 | BO36: =SUM($B$36:R36) -> 0 | BP36: =SUM($B$36:S36) -> 0 | BQ36: =SUM($B$36:T36) -> 0 | BR36: =SUM($B$36:V36) -> 0 | BS36: =SUM($BR$32:BR36) -> 0 | BT36: =BR36+X36 -> 0 | BU36: =SUM($BT$32:BT36) -> 0
A37: Sat | W37: =SUM(B37:V37) -> 0 | X37: =SUM(AD37:AW37)*0.1 -> 0 | Y37: =W37+X37 -> 0 | AB37: =AB23+W37 -> 0 | AC37: Sat | AD37: =IF(B37 > 0, IF(AD36 > 0, AD36 + 1, 0.1), 0) -> 0 | AE37: =IF(C37 > 0, IF(AE36 > 0, AE36 + 1, 0.1), 0) -> 0 | AF37: =IF(D37 > 0, IF(AF36 > 0, AF36 + 1, 0.1), 0) -> 0 | AG37: =IF(E37 > 0, IF(AG36 > 0, AG36 + 1, 0.1), 0) -> 0 | AH37: =IF(F37 > 0, IF(AH36 > 0, AH36 + 1, 0.1), 0) -> 0 | AI37: =IF(G37 > 0, IF(AI36 > 0, AI36 + 1, 0.1), 0) -> 0 | AJ37: =IF(H37 > 0, IF(AJ36 > 0, AJ36 + 1, 0.1), 0) -> 0 | AK37: =IF(I37 > 0, IF(AK36 > 0, AK36 + 1, 0.1), 0) -> 0 | ... AT37: =IF(R37 > 0, IF(AT36 > 0, AT36 + 1, 0.1), 0) -> 0 | AU37: =IF(S37 > 0, IF(AU29> 0, AU29 + 1, 0.1), 0) -> 0 | AV37: =IF(T37 > 0, IF(AV36 > 0, AV36 + 1, 0.1), 0) -> 0 | AW37: =IF(U37 > 0, IF(AW36 > 0, AW36 + 1, 0.1), 0) -> 0 | AY37: =SUM($B$37:B37) -> 0 | AZ37: =SUM($B$37:C37) -> 0 | BA37: =SUM($B$37:D37) -> 0 | BB37: =SUM($B$37:E37) -> 0 | BC37: =SUM($B$37:F37) -> 0 | BD37: =SUM($B$37:G37) -> 0 | BE37: =SUM($B$37:H37) -> 0 | BF37: =SUM($B$37:I37) -> 0 | ... BJ37: =SUM($B$37:M37) -> 0 | BK37: =SUM($B$37:Q37) -> 0 | BL37: =SUM($B$37:N37) -> 0 | BM37: =SUM($B$37:O37) -> 0 | BN37: =SUM($B$37:P37) -> 0 | BO37: =SUM($B$37:R37) -> 0 | BP37: =SUM($B$37:S37) -> 0 | BQ37: =SUM($B$37:T37) -> 0 | BR37: =SUM($B$37:V37) -> 0 | BS37: =SUM($BR$32:BR37) -> 0 | BT37: =BR37+X37 -> 0 | BU37: =SUM($BT$32:BT37) -> 0
A38: Sun | W38: =SUM(B38:V38) -> 0 | X38: =SUM(AD38:AW38)*0.1 -> 0 | Y38: =W38+X38 -> 0 | AB38: =AB24+W38 -> 0 | AC38: Sun | AD38: =IF(B38 > 0, IF(AD37 > 0, AD37 + 1, 0.1), 0) -> 0 | AE38: =IF(C38 > 0, IF(AE37 > 0, AE37 + 1, 0.1), 0) -> 0 | AF38: =IF(D38 > 0, IF(AF37 > 0, AF37 + 1, 0.1), 0) -> 0 | AG38: =IF(E38 > 0, IF(AG37 > 0, AG37 + 1, 0.1), 0) -> 0 | AH38: =IF(F38 > 0, IF(AH37 > 0, AH37 + 1, 0.1), 0) -> 0 | AI38: =IF(G38 > 0, IF(AI37 > 0, AI37 + 1, 0.1), 0) -> 0 | AJ38: =IF(H38 > 0, IF(AJ37 > 0, AJ37 + 1, 0.1), 0) -> 0 | AK38: =IF(I38 > 0, IF(AK37 > 0, AK37 + 1, 0.1), 0) -> 0 | ... AT38: =IF(R38 > 0, IF(AT37 > 0, AT37 + 1, 0.1), 0) -> 0 | AU38: =IF(S38 > 0, IF(AU30> 0, AU30 + 1, 0.1), 0) -> 0 | AV38: =IF(T38 > 0, IF(AV37 > 0, AV37 + 1, 0.1), 0) -> 0 | AW38: =IF(U38 > 0, IF(AW37 > 0, AW37 + 1, 0.1), 0) -> 0 | AY38: =SUM($B$38:B38) -> 0 | AZ38: =SUM($B$38:C38) -> 0 | BA38: =SUM($B$38:D38) -> 0 | BB38: =SUM($B$38:E38) -> 0 | BC38: =SUM($B$38:F38) -> 0 | BD38: =SUM($B$38:G38) -> 0 | BE38: =SUM($B$38:H38) -> 0 | BF38: =SUM($B$38:I38) -> 0 | ... BJ38: =SUM($B$38:M38) -> 0 | BK38: =SUM($B$38:Q38) -> 0 | BL38: =SUM($B$38:N38) -> 0 | BM38: =SUM($B$38:O38) -> 0 | BN38: =SUM($B$38:P38) -> 0 | BO38: =SUM($B$38:R38) -> 0 | BP38: =SUM($B$38:S38) -> 0 | BQ38: =SUM($B$38:T38) -> 0 | BR38: =SUM($B$38:V38) -> 0 | BS38: =SUM($BR$32:BR38) -> 0 | BT38: =BR38+X38 -> 0 | BU38: =SUM($BT$32:BT38) -> 0
A39: Total ind | B39: =SUM(B32:B38) -> 0 | C39: =SUM(C32:C38) -> 0 | D39: =SUM(D32:D38) -> 0 | E39: =SUM(E32:E38) -> 0 | F39: =SUM(F32:F38) -> 0 | G39: =SUM(G32:G38) -> 0 | H39: =SUM(H32:H38) -> 0 | I39: =SUM(I32:I38) -> 0 | ... W39: =SUM(W32:W38) -> 0 | Z39: How's your week?:
A40: ratio | B40: =B39-B25 -> 0 | C40: =C39-C25 -> 0 | D40: =D39-D25 -> 0 | E40: =E39-E25 -> 0 | F40: =F39-F25 -> 0 | G40: =G39-G25 -> 0 | H40: =H39-H25 -> 0 | I40: =I39-I25 -> 0 | ... V40: =V39-V25 -> 0 | W40: =SUM(B40:V40) -> 0
...

Sheet charts
O2: Cumulative charts
G4: Start Date | J4: End Date
B6: Conclusion: | G6: =Game!D3 -> 46027 | H6: - | J6: =Game!C157 -> 46110
A7: Charts
A8: Comparison Weekly
A9: Comparison Weekly
A10: Comparison Weekly
A11: Comparison Weekly
A12: Comparison Weekly
A13: Comparison Weekly
A14: Comparison Weekly
A15: Comparison Weekly
A16: Comparison Weekly
A17: Comparison Weekly
A18: Comparison Weekly
... A235: Everyday performance(Streak Bonus)
B240: week 1: | C240: 36994 | D240: =C240+6 -> 37000
B274: week 2: | C274: =Game!B17 -> 46034 | D274: =C274+6 -> 46040
B308: week 3: | C308: =Game!B31 -> 46041 | D308: =C308+6 -> 46047
B341: week 4: | C341: =Game!B45 -> 46048 | D341: =C341+6 -> 46054
B374: week 5: | C374: =Game!B59 -> 46055 | D374: =C374+6 -> 46061
B409: week 6: | C409: =Game!B73 -> 46062 | D409: =C409+6 -> 46068
B443: week 7: | C443: =Game!B87 -> 46069 | D443: =C443+6 -> 46075
B474: week 8 | C474: =Game!B101 -> 46076 | D474: =C474+6 -> 46082
B506: week 9: | C506: =Game!B115 -> 46083 | D506: =C506+6 -> 46089
B541: week 10: | C541: =Game!B129 -> 46090 | D541: =C541+6 -> 46096
B577: week 11 | C577: =Game!B143 -> 46097 | D577: =C577+6 -> 46103
B611: week 12: | C611: =Game!B157 -> 46104 | D611: =C611+6 -> 46110

Sheet optional
B1: Rant(optional) | C1: Moment Of the day? | D1: Funny Moment (s)? | E1: tough situation(s) | F1: Song(s) Of the day | I1: ( this sheet is still in experimental stage)
A2: Week | B2: 36994 | C2: =B2+6 -> 37000
A3: Mon
A4: Tue
A5: Wed
A6: Thu
A7: Fri
A8: Sat
A9: Sun
A11: week2 | B11: =C2+1 -> 37001 | C11: =B11+6 -> 37007
A12: Mon
A13: Tue
A14: Wed
A15: Thu
A16: Fri
A17: Sat
A18: Sun
A20: week3 | B20: =C11+1 -> 37008 | C20: =B20+6 -> 37014
A21: Mon
A22: Tue
A23: Wed
A24: Thu
A25: Fri
A26: Sat
A27: Sun
A29: week4 | B29: =C20+1 -> 37015 | C29: =B29+6 -> 37021
A30: Mon
A31: Tue
A32: Wed
A33: Thu
A34: Fri
A35: Sat
A36: Sun
A39: week 5 | B39: =C29+1 -> 37022 | C39: =B39+6 -> 37028
A40: Mon
A41: Tue
A42: Wed
A43: Thu
A44: Fri
A45: Sat
...

Sheet PJ-about,rules
K1: Productive Journaling
K2: "Every action of yours holds a VALUE ."
A4: Like the cliche-old saying: "Trying to live today a wee bit better than before." (And I dont mean by trying to be more productive for its own sake, but by actually enjoying your day. Yes, we must push ourselves forward and survive tough situations. But what is being productive without enjoying or striving to be productive? ) Productivity is not just advancing forward in life, but also being content with what you have. And THIS tool helps you track where you are standing, and helps you enjoy ̷b̷̷e̷̷i̷̷n̷̷g̷ ̷p̷̷r̷̷o̷̷d̷̷u̷̷c̷̷t̷̷i̷̷v̷̷e̷ life.
A6: What is Productive Journaling? An idea centered on awareness of your actions . A private space to notice effort, patterns, and progress over time. Productive journaling not only measures your daily performance but mainly to stay aware of how you spend your days in a leightweight way which can demand about 5 minutes of your everyday. More than focusing on perfect routines or streaks, it focuses on honest reflection. You log what you actually did, how your day felt, and how you chose to use your time. It gives you the oppurtunity to reward yourself of those efforts which will go unheard/unnoticed but you. There’s no “good” or “bad” day here. Only days that happened. ~By also pushing you to maintain consistent-intensity of every activity/interest of yours. Over time, this helps you see where your energy goes, what you value, and how your days naturally balance work, rest, and interests. A journal that is done differently than a traditional diary (can be one if you want to). Not a productivity system that tells you what to do Everything stays with you. You decide what matters, how much detail to add, and how seriously to take it.
A8: How to use/instructions This template is meant to be simple. You don’t need to understand everything before starting. Step 1 — One-time setup (≈ 5 minutes) In the setup sheet, edit the activities, hobbies, or qualities that matter to you. You decide what deserves attention — and how much. There’s no “correct” scoring system here. Set scores in a way that feels fair and realistic to you. (edit the hobby comments/descriptions 'rightclick column->edit comment') Step 2 — Daily use (≈ 1–2 minutes) At the end of the day/the next day morning/anytime you prefer, give yourself a score honestly write a short line about how the day felt, or give it a title That’s enough. (If you want to vent, reflect deeper, or write more — you can. If not, a single sentence is perfectly fine.) Step 3 — Let patterns form Use it daily without trying to optimize it early. Over time, the charts and summaries begin to show patterns and enjoy! Good days, bad days, boring days — they all count. That’s the whole system.
U12: Contact Details:
A13: HIGHLY RECOMMENDED you try this journal/template for 8 days. | U13: just hit me up on ig | W13: @vilgakz
A14: or atleast 2 days to get a gist of the whole idea. And , | U14: for boomers | W14: +91 8050279050 | Y14: + 44 7341671943
A15: Please leave us your valuable feeback | E15: Click me | W15: @kaipasaibhargav83@gmail.com
U16: for redditors | W16: r/theweirdlyguy
A37: Productive Journaling is a life-time observation . Hence,If you wish to continue using it long term, this is a recommended structure, and The structure is very broad and long-term
A38: 12 Weeks + 1week rest = 1 edition | E38: -> | F38: You can take that 1 week break whenever you want in between the whole 12 weeks. If you don’t want to take any break, you can add that to the next edition.
A39: 3 editions + 1 restful edition = 1 chapter | E39: -> | F39: 1 restful edition is nothing but 12 weeks of rest. | K39: Now u can use it as rest if you want but this period is exists so you still be productive, and etc.
F40: 1 month of | K40: but No score involved. A reminder that you are being productive for yourself but not to score max.You can use this period to reflect, evaluate your actions, priorities
A42: why 12 weeks? Do you know us humans have the capability to achieve a 12 month resolve/goal compressed within 12 weeks if done right?
M43: (~The 12 week year)
